Workbook

Sheet Dashboard
B2: WRITING QUEST — Arnav Kashyap
B4: 60-Day Writing Improvement Program · Live Dashboard
B7: Total XP | D7: Current Streak | F7: Best Streak | H7: Days Completed
B8: =SUM('Daily Log'!H4:H63) -> 0 | D8: ='Daily Log'!K65 -> 0 | F8: ='Daily Log'!K66 -> 0 | H8: =COUNTIF('Daily Log'!E4:E63,"Yes") -> 0
B12: Current Level | F12: Title
B13: =IF(B8>=1400,"Lv 8",IF(B8>=1100,"Lv 7",IF(B8>=800,"Lv 6",IF(B8>=550,"Lv 5",IF(B8>=350,"Lv 4",IF(B8>=180,"Lv 3",IF(B8>=60,"Lv 2","Lv 1"))))))) -> Lv 1 | F13: =IF(B8>=1400,"Class 6 Champion",IF(B8>=1100,"Opinion Warrior",IF(B8>=800,"Story Captain",IF(B8>=550,"Spelling Sentinel",IF(B8>=350,"Paragraph Mage",IF(B8>=180,"Sentence Knight",IF(B8>=60,"Word Cadet","Pencil Apprentice"))))))) -> Pencil Apprentice
B18: 60-Day Progress (each box = 1 day; green = mission done)
B19: =IF('Daily Log'!E4="Yes",1,"") | C19: =IF('Daily Log'!E5="Yes",2,"") | D19: =IF('Daily Log'!E6="Yes",3,"") | E19: =IF('Daily Log'!E7="Yes",4,"") | F19: =IF('Daily Log'!E8="Yes",5,"") | G19: =IF('Daily Log'!E9="Yes",6,"") | H19: =IF('Daily Log'!E10="Yes",7,"") | I19: =IF('Daily Log'!E11="Yes",8,"") | J19: =IF('Daily Log'!E12="Yes",9,"") | K19: =IF('Daily Log'!E13="Yes",10,"")
B20: =IF('Daily Log'!E14="Yes",11,"") | C20: =IF('Daily Log'!E15="Yes",12,"") | D20: =IF('Daily Log'!E16="Yes",13,"") | E20: =IF('Daily Log'!E17="Yes",14,"") | F20: =IF('Daily Log'!E18="Yes",15,"") | G20: =IF('Daily Log'!E19="Yes",16,"") | H20: =IF('Daily Log'!E20="Yes",17,"") | I20: =IF('Daily Log'!E21="Yes",18,"") | J20: =IF('Daily Log'!E22="Yes",19,"") | K20: =IF('Daily Log'!E23="Yes",20,"")
B21: =IF('Daily Log'!E24="Yes",21,"") | C21: =IF('Daily Log'!E25="Yes",22,"") | D21: =IF('Daily Log'!E26="Yes",23,"") | E21: =IF('Daily Log'!E27="Yes",24,"") | F21: =IF('Daily Log'!E28="Yes",25,"") | G21: =IF('Daily Log'!E29="Yes",26,"") | H21: =IF('Daily Log'!E30="Yes",27,"") | I21: =IF('Daily Log'!E31="Yes",28,"") | J21: =IF('Daily Log'!E32="Yes",29,"") | K21: =IF('Daily Log'!E33="Yes",30,"")
B22: =IF('Daily Log'!E34="Yes",31,"") | C22: =IF('Daily Log'!E35="Yes",32,"") | D22: =IF('Daily Log'!E36="Yes",33,"") | E22: =IF('Daily Log'!E37="Yes",34,"") | F22: =IF('Daily Log'!E38="Yes",35,"") | G22: =IF('Daily Log'!E39="Yes",36,"") | H22: =IF('Daily Log'!E40="Yes",37,"") | I22: =IF('Daily Log'!E41="Yes",38,"") | J22: =IF('Daily Log'!E42="Yes",39,"") | K22: =IF('Daily Log'!E43="Yes",40,"")
B23: =IF('Daily Log'!E44="Yes",41,"") | C23: =IF('Daily Log'!E45="Yes",42,"") | D23: =IF('Daily Log'!E46="Yes",43,"") | E23: =IF('Daily Log'!E47="Yes",44,"") | F23: =IF('Daily Log'!E48="Yes",45,"") | G23: =IF('Daily Log'!E49="Yes",46,"") | H23: =IF('Daily Log'!E50="Yes",47,"") | I23: =IF('Daily Log'!E51="Yes",48,"") | J23: =IF('Daily Log'!E52="Yes",49,"") | K23: =IF('Daily Log'!E53="Yes",50,"")
B24: =IF('Daily Log'!E54="Yes",51,"") | C24: =IF('Daily Log'!E55="Yes",52,"") | D24: =IF('Daily Log'!E56="Yes",53,"") | E24: =IF('Daily Log'!E57="Yes",54,"") | F24: =IF('Daily Log'!E58="Yes",55,"") | G24: =IF('Daily Log'!E59="Yes",56,"") | H24: =IF('Daily Log'!E60="Yes",57,"") | I24: =IF('Daily Log'!E61="Yes",58,"") | J24: =IF('Daily Log'!E62="Yes",59,"") | K24: =IF('Daily Log'!E63="Yes",60,"")
B26: =IF(B8>=1400,"GRAND FINAL UNLOCKED! 🏆","XP to next level: " & IF(B8<60,60-B8,IF(B8<180,180-B8,IF(B8<350,350-B8,IF(B8<550,550-B8,IF(B8<800,800-B8,IF(B8<1100,1100-B8,IF(B8<1400,1400-B8,0)))))))) -> XP to next level: 60
B28: Today's Tip
B29: =INDEX({"Just start. Finishing IS winning today.";"Set the timer. 20 minutes. Phone away.";"Two specific praises + one suggestion. That's the whole review.";"If today feels heavy, do the 5-min Lite Day. Streak still counts.";"Speed today, neatness later. Trust the plan.";"Read it back aloud. Circle one word you're proud of.";"Boss Day soon? Big celebration energy. You've earned it."}, MOD(DAY(TODAY()),7)+1) -> Speed today, neatness later. Trust the plan.

Sheet Daily Log
A1: Daily Log — fill the Date and Mission Done column. Everything else is automatic.
A3: Day | B3: Date | C3: Theme | D3: Phase | E3: Mission Done? | F3: Lines Written | G3: Spell Words Used | H3: XP Today | I3: Streak Day | J3: Mood (1–5) | K3: Notes
A4: 1 | C4: Onboarding | D4: Phase 1 · Fluency | H4: =IF(E4="Yes",10+IF(AND(F4<>"",F4>=IF(1<=7,3,IF(1<=14,5,IF(1<=21,7,IF(1<=42,8,10))))),2,0)+IF(G4>0,MIN(G4,3),0)+0+IF(MOD(I4,7)=0,IF(I4>0,5,0),0),IF(E4="Lite",3,0)) -> 0 | I4: =IF(OR(E4="Yes",E4="Lite"),1,0) -> 0
A5: 2 | C5: Onboarding | D5: Phase 1 · Fluency | H5: =IF(E5="Yes",10+IF(AND(F5<>"",F5>=IF(2<=7,3,IF(2<=14,5,IF(2<=21,7,IF(2<=42,8,10))))),2,0)+IF(G5>0,MIN(G5,3),0)+0+IF(MOD(I5,7)=0,IF(I5>0,5,0),0),IF(E5="Lite",3,0)) -> 0 | I5: =IF(OR(E5="Yes",E5="Lite"),IF(OR(E4="Yes",E4="Lite"),I4+1,1),IF(E5="Freeze",I4,0)) -> 0
A6: 3 | C6: Onboarding | D6: Phase 1 · Fluency | H6: =IF(E6="Yes",10+IF(AND(F6<>"",F6>=IF(3<=7,3,IF(3<=14,5,IF(3<=21,7,IF(3<=42,8,10))))),2,0)+IF(G6>0,MIN(G6,3),0)+0+IF(MOD(I6,7)=0,IF(I6>0,5,0),0),IF(E6="Lite",3,0)) -> 0 | I6: =IF(OR(E6="Yes",E6="Lite"),IF(OR(E5="Yes",E5="Lite"),I5+1,1),IF(E6="Freeze",I5,0)) -> 0
A7: 4 | C7: Onboarding | D7: Phase 1 · Fluency | H7: =IF(E7="Yes",10+IF(AND(F7<>"",F7>=IF(4<=7,3,IF(4<=14,5,IF(4<=21,7,IF(4<=42,8,10))))),2,0)+IF(G7>0,MIN(G7,3),0)+0+IF(MOD(I7,7)=0,IF(I7>0,5,0),0),IF(E7="Lite",3,0)) -> 0 | I7: =IF(OR(E7="Yes",E7="Lite"),IF(OR(E6="Yes",E6="Lite"),I6+1,1),IF(E7="Freeze",I6,0)) -> 0
A8: 5 | C8: Onboarding | D8: Phase 1 · Fluency | H8: =IF(E8="Yes",10+IF(AND(F8<>"",F8>=IF(5<=7,3,IF(5<=14,5,IF(5<=21,7,IF(5<=42,8,10))))),2,0)+IF(G8>0,MIN(G8,3),0)+0+IF(MOD(I8,7)=0,IF(I8>0,5,0),0),IF(E8="Lite",3,0)) -> 0 | I8: =IF(OR(E8="Yes",E8="Lite"),IF(OR(E7="Yes",E7="Lite"),I7+1,1),IF(E8="Freeze",I7,0)) -> 0
A9: 6 | C9: Onboarding | D9: Phase 1 · Fluency | H9: =IF(E9="Yes",10+IF(AND(F9<>"",F9>=IF(6<=7,3,IF(6<=14,5,IF(6<=21,7,IF(6<=42,8,10))))),2,0)+IF(G9>0,MIN(G9,3),0)+0+IF(MOD(I9,7)=0,IF(I9>0,5,0),0),IF(E9="Lite",3,0)) -> 0 | I9: =IF(OR(E9="Yes",E9="Lite"),IF(OR(E8="Yes",E8="Lite"),I8+1,1),IF(E9="Freeze",I8,0)) -> 0
A10: 7 | C10: Onboarding | D10: Phase 1 · Fluency | H10: =IF(E10="Yes",10+IF(AND(F10<>"",F10>=IF(7<=7,3,IF(7<=14,5,IF(7<=21,7,IF(7<=42,8,10))))),2,0)+IF(G10>0,MIN(G10,3),0)+0+IF(MOD(I10,7)=0,IF(I10>0,5,0),0),IF(E10="Lite",3,0)) -> 0 | I10: =IF(OR(E10="Yes",E10="Lite"),IF(OR(E9="Yes",E9="Lite"),I9+1,1),IF(E10="Freeze",I9,0)) -> 0
A11: 8 | C11: Speed drills | D11: Phase 1 · Fluency | H11: =IF(E11="Yes",10+IF(AND(F11<>"",F11>=IF(8<=7,3,IF(8<=14,5,IF(8<=21,7,IF(8<=42,8,10))))),2,0)+IF(G11>0,MIN(G11,3),0)+0+IF(MOD(I11,7)=0,IF(I11>0,5,0),0),IF(E11="Lite",3,0)) -> 0 | I11: =IF(OR(E11="Yes",E11="Lite"),IF(OR(E10="Yes",E10="Lite"),I10+1,1),IF(E11="Freeze",I10,0)) -> 0
A12: 9 | C12: Speed drills | D12: Phase 1 · Fluency | H12: =IF(E12="Yes",10+IF(AND(F12<>"",F12>=IF(9<=7,3,IF(9<=14,5,IF(9<=21,7,IF(9<=42,8,10))))),2,0)+IF(G12>0,MIN(G12,3),0)+0+IF(MOD(I12,7)=0,IF(I12>0,5,0),0),IF(E12="Lite",3,0)) -> 0 | I12: =IF(OR(E12="Yes",E12="Lite"),IF(OR(E11="Yes",E11="Lite"),I11+1,1),IF(E12="Freeze",I11,0)) -> 0
A13: 10 | C13: ⚔️ BOSS · Speed drills | D13: Phase 1 · Fluency | H13: =IF(E13="Yes",10+IF(AND(F13<>"",F13>=IF(10<=7,3,IF(10<=14,5,IF(10<=21,7,IF(10<=42,8,10))))),2,0)+IF(G13>0,MIN(G13,3),0)+15+IF(MOD(I13,7)=0,IF(I13>0,5,0),0),IF(E13="Lite",3,0)) -> 0 | I13: =IF(OR(E13="Yes",E13="Lite"),IF(OR(E12="Yes",E12="Lite"),I12+1,1),IF(E13="Freeze",I12,0)) -> 0
A14: 11 | C14: Speed drills | D14: Phase 1 · Fluency | H14: =IF(E14="Yes",10+IF(AND(F14<>"",F14>=IF(11<=7,3,IF(11<=14,5,IF(11<=21,7,IF(11<=42,8,10))))),2,0)+IF(G14>0,MIN(G14,3),0)+0+IF(MOD(I14,7)=0,IF(I14>0,5,0),0),IF(E14="Lite",3,0)) -> 0 | I14: =IF(OR(E14="Yes",E14="Lite"),IF(OR(E13="Yes",E13="Lite"),I13+1,1),IF(E14="Freeze",I13,0)) -> 0
A15: 12 | C15: Speed drills | D15: Phase 1 · Fluency | H15: =IF(E15="Yes",10+IF(AND(F15<>"",F15>=IF(12<=7,3,IF(12<=14,5,IF(12<=21,7,IF(12<=42,8,10))))),2,0)+IF(G15>0,MIN(G15,3),0)+0+IF(MOD(I15,7)=0,IF(I15>0,5,0),0),IF(E15="Lite",3,0)) -> 0 | I15: =IF(OR(E15="Yes",E15="Lite"),IF(OR(E14="Yes",E14="Lite"),I14+1,1),IF(E15="Freeze",I14,0)) -> 0
A16: 13 | C16: Speed drills | D16: Phase 1 · Fluency | H16: =IF(E16="Yes",10+IF(AND(F16<>"",F16>=IF(13<=7,3,IF(13<=14,5,IF(13<=21,7,IF(13<=42,8,10))))),2,0)+IF(G16>0,MIN(G16,3),0)+0+IF(MOD(I16,7)=0,IF(I16>0,5,0),0),IF(E16="Lite",3,0)) -> 0 | I16: =IF(OR(E16="Yes",E16="Lite"),IF(OR(E15="Yes",E15="Lite"),I15+1,1),IF(E16="Freeze",I15,0)) -> 0
A17: 14 | C17: Speed drills | D17: Phase 1 · Fluency | H17: =IF(E17="Yes",10+IF(AND(F17<>"",F17>=IF(14<=7,3,IF(14<=14,5,IF(14<=21,7,IF(14<=42,8,10))))),2,0)+IF(G17>0,MIN(G17,3),0)+0+IF(MOD(I17,7)=0,IF(I17>0,5,0),0),IF(E17="Lite",3,0)) -> 0 | I17: =IF(OR(E17="Yes",E17="Lite"),IF(OR(E16="Yes",E16="Lite"),I16+1,1),IF(E17="Freeze",I16,0)) -> 0
A18: 15 | C18: Story mode | D18: Phase 1 · Fluency | H18: =IF(E18="Yes",10+IF(AND(F18<>"",F18>=IF(15<=7,3,IF(15<=14,5,IF(15<=21,7,IF(15<=42,8,10))))),2,0)+IF(G18>0,MIN(G18,3),0)+0+IF(MOD(I18,7)=0,IF(I18>0,5,0),0),IF(E18="Lite",3,0)) -> 0 | I18: =IF(OR(E18="Yes",E18="Lite"),IF(OR(E17="Yes",E17="Lite"),I17+1,1),IF(E18="Freeze",I17,0)) -> 0
A19: 16 | C19: Story mode | D19: Phase 1 · Fluency | H19: =IF(E19="Yes",10+IF(AND(F19<>"",F19>=IF(16<=7,3,IF(16<=14,5,IF(16<=21,7,IF(16<=42,8,10))))),2,0)+IF(G19>0,MIN(G19,3),0)+0+IF(MOD(I19,7)=0,IF(I19>0,5,0),0),IF(E19="Lite",3,0)) -> 0 | I19: =IF(OR(E19="Yes",E19="Lite"),IF(OR(E18="Yes",E18="Lite"),I18+1,1),IF(E19="Freeze",I18,0)) -> 0
A20: 17 | C20: Story mode | D20: Phase 1 · Fluency | H20: =IF(E20="Yes",10+IF(AND(F20<>"",F20>=IF(17<=7,3,IF(17<=14,5,IF(17<=21,7,IF(17<=42,8,10))))),2,0)+IF(G20>0,MIN(G20,3),0)+0+IF(MOD(I20,7)=0,IF(I20>0,5,0),0),IF(E20="Lite",3,0)) -> 0 | I20: =IF(OR(E20="Yes",E20="Lite"),IF(OR(E19="Yes",E19="Lite"),I19+1,1),IF(E20="Freeze",I19,0)) -> 0
A21: 18 | C21: Story mode | D21: Phase 1 · Fluency | H21: =IF(E21="Yes",10+IF(AND(F21<>"",F21>=IF(18<=7,3,IF(18<=14,5,IF(18<=21,7,IF(18<=42,8,10))))),2,0)+IF(G21>0,MIN(G21,3),0)+0+IF(MOD(I21,7)=0,IF(I21>0,5,0),0),IF(E21="Lite",3,0)) -> 0 | I21: =IF(OR(E21="Yes",E21="Lite"),IF(OR(E20="Yes",E20="Lite"),I20+1,1),IF(E21="Freeze",I20,0)) -> 0
A22: 19 | C22: Story mode | D22: Phase 1 · Fluency | H22: =IF(E22="Yes",10+IF(AND(F22<>"",F22>=IF(19<=7,3,IF(19<=14,5,IF(19<=21,7,IF(19<=42,8,10))))),2,0)+IF(G22>0,MIN(G22,3),0)+0+IF(MOD(I22,7)=0,IF(I22>0,5,0),0),IF(E22="Lite",3,0)) -> 0 | I22: =IF(OR(E22="Yes",E22="Lite"),IF(OR(E21="Yes",E21="Lite"),I21+1,1),IF(E22="Freeze",I21,0)) -> 0
A23: 20 | C23: ⚔️ BOSS · Story mode | D23: Phase 1 · Fluency | H23: =IF(E23="Yes",10+IF(AND(F23<>"",F23>=IF(20<=7,3,IF(20<=14,5,IF(20<=21,7,IF(20<=42,8,10))))),2,0)+IF(G23>0,MIN(G23,3),0)+15+IF(MOD(I23,7)=0,IF(I23>0,5,0),0),IF(E23="Lite",3,0)) -> 0 | I23: =IF(OR(E23="Yes",E23="Lite"),IF(OR(E22="Yes",E22="Lite"),I22+1,1),IF(E23="Freeze",I22,0)) -> 0
A24: 21 | C24: Story mode | D24: Phase 1 · Fluency | H24: =IF(E24="Yes",10+IF(AND(F24<>"",F24>=IF(21<=7,3,IF(21<=14,5,IF(21<=21,7,IF(21<=42,8,10))))),2,0)+IF(G24>0,MIN(G24,3),0)+0+IF(MOD(I24,7)=0,IF(I24>0,5,0),0),IF(E24="Lite",3,0)) -> 0 | I24: =IF(OR(E24="Yes",E24="Lite"),IF(OR(E23="Yes",E23="Lite"),I23+1,1),IF(E24="Freeze",I23,0)) -> 0
A25: 22 | C25: Paragraph shape | D25: Phase 2 · Structure | H25: =IF(E25="Yes",10+IF(AND(F25<>"",F25>=IF(22<=7,3,IF(22<=14,5,IF(22<=21,7,IF(22<=42,8,10))))),2,0)+IF(G25>0,MIN(G25,3),0)+0+IF(MOD(I25,7)=0,IF(I25>0,5,0),0),IF(E25="Lite",3,0)) -> 0 | I25: =IF(OR(E25="Yes",E25="Lite"),IF(OR(E24="Yes",E24="Lite"),I24+1,1),IF(E25="Freeze",I24,0)) -> 0
A26: 23 | C26: Paragraph shape | D26: Phase 2 · Structure | H26: =IF(E26="Yes",10+IF(AND(F26<>"",F26>=IF(23<=7,3,IF(23<=14,5,IF(23<=21,7,IF(23<=42,8,10))))),2,0)+IF(G26>0,MIN(G26,3),0)+0+IF(MOD(I26,7)=0,IF(I26>0,5,0),0),IF(E26="Lite",3,0)) -> 0 | I26: =IF(OR(E26="Yes",E26="Lite"),IF(OR(E25="Yes",E25="Lite"),I25+1,1),IF(E26="Freeze",I25,0)) -> 0
A27: 24 | C27: Paragraph shape | D27: Phase 2 · Structure | H27: =IF(E27="Yes",10+IF(AND(F27<>"",F27>=IF(24<=7,3,IF(24<=14,5,IF(24<=21,7,IF(24<=42,8,10))))),2,0)+IF(G27>0,MIN(G27,3),0)+0+IF(MOD(I27,7)=0,IF(I27>0,5,0),0),IF(E27="Lite",3,0)) -> 0 | I27: =IF(OR(E27="Yes",E27="Lite"),IF(OR(E26="Yes",E26="Lite"),I26+1,1),IF(E27="Freeze",I26,0)) -> 0
A28: 25 | C28: Paragraph shape | D28: Phase 2 · Structure | H28: =IF(E28="Yes",10+IF(AND(F28<>"",F28>=IF(25<=7,3,IF(25<=14,5,IF(25<=21,7,IF(25<=42,8,10))))),2,0)+IF(G28>0,MIN(G28,3),0)+0+IF(MOD(I28,7)=0,IF(I28>0,5,0),0),IF(E28="Lite",3,0)) -> 0 | I28: =IF(OR(E28="Yes",E28="Lite"),IF(OR(E27="Yes",E27="Lite"),I27+1,1),IF(E28="Freeze",I27,0)) -> 0
A29: 26 | C29: Paragraph shape | D29: Phase 2 · Structure | H29: =IF(E29="Yes",10+IF(AND(F29<>"",F29>=IF(26<=7,3,IF(26<=14,5,IF(26<=21,7,IF(26<=42,8,10))))),2,0)+IF(G29>0,MIN(G29,3),0)+0+IF(MOD(I29,7)=0,IF(I29>0,5,0),0),IF(E29="Lite",3,0)) -> 0 | I29: =IF(OR(E29="Yes",E29="Lite"),IF(OR(E28="Yes",E28="Lite"),I28+1,1),IF(E29="Freeze",I28,0)) -> 0
A30: 27 | C30: Paragraph shape | D30: Phase 2 · Structure | H30: =IF(E30="Yes",10+IF(AND(F30<>"",F30>=IF(27<=7,3,IF(27<=14,5,IF(27<=21,7,IF(27<=42,8,10))))),2,0)+IF(G30>0,MIN(G30,3),0)+0+IF(MOD(I30,7)=0,IF(I30>0,5,0),0),IF(E30="Lite",3,0)) -> 0 | I30: =IF(OR(E30="Yes",E30="Lite"),IF(OR(E29="Yes",E29="Lite"),I29+1,1),IF(E30="Freeze",I29,0)) -> 0
A31: 28 | C31: Paragraph shape | D31: Phase 2 · Structure | H31: =IF(E31="Yes",10+IF(AND(F31<>"",F31>=IF(28<=7,3,IF(28<=14,5,IF(28<=21,7,IF(28<=42,8,10))))),2,0)+IF(G31>0,MIN(G31,3),0)+0+IF(MOD(I31,7)=0,IF(I31>0,5,0),0),IF(E31="Lite",3,0)) -> 0 | I31: =IF(OR(E31="Yes",E31="Lite"),IF(OR(E30="Yes",E30="Lite"),I30+1,1),IF(E31="Freeze",I30,0)) -> 0
A32: 29 | C32: Spelling bank | D32: Phase 2 · Structure | H32: =IF(E32="Yes",10+IF(AND(F32<>"",F32>=IF(29<=7,3,IF(29<=14,5,IF(29<=21,7,IF(29<=42,8,10))))),2,0)+IF(G32>0,MIN(G32,3),0)+0+IF(MOD(I32,7)=0,IF(I32>0,5,0),0),IF(E32="Lite",3,0)) -> 0 | I32: =IF(OR(E32="Yes",E32="Lite"),IF(OR(E31="Yes",E31="Lite"),I31+1,1),IF(E32="Freeze",I31,0)) -> 0
A33: 30 | C33: ⚔️ BOSS · Spelling bank | D33: Phase 2 · Structure | H33: =IF(E33="Yes",10+IF(AND(F33<>"",F33>=IF(30<=7,3,IF(30<=14,5,IF(30<=21,7,IF(30<=42,8,10))))),2,0)+IF(G33>0,MIN(G33,3),0)+15+IF(MOD(I33,7)=0,IF(I33>0,5,0),0),IF(E33="Lite",3,0)) -> 0 | I33: =IF(OR(E33="Yes",E33="Lite"),IF(OR(E32="Yes",E32="Lite"),I32+1,1),IF(E33="Freeze",I32,0)) -> 0
A34: 31 | C34: Spelling bank | D34: Phase 2 · Structure | H34: =IF(E34="Yes",10+IF(AND(F34<>"",F34>=IF(31<=7,3,IF(31<=14,5,IF(31<=21,7,IF(31<=42,8,10))))),2,0)+IF(G34>0,MIN(G34,3),0)+0+IF(MOD(I34,7)=0,IF(I34>0,5,0),0),IF(E34="Lite",3,0)) -> 0 | I34: =IF(OR(E34="Yes",E34="Lite"),IF(OR(E33="Yes",E33="Lite"),I33+1,1),IF(E34="Freeze",I33,0)) -> 0
A35: 32 | C35: Spelling bank | D35: Phase 2 · Structure | H35: =IF(E35="Yes",10+IF(AND(F35<>"",F35>=IF(32<=7,3,IF(32<=14,5,IF(32<=21,7,IF(32<=42,8,10))))),2,0)+IF(G35>0,MIN(G35,3),0)+0+IF(MOD(I35,7)=0,IF(I35>0,5,0),0),IF(E35="Lite",3,0)) -> 0 | I35: =IF(OR(E35="Yes",E35="Lite"),IF(OR(E34="Yes",E34="Lite"),I34+1,1),IF(E35="Freeze",I34,0)) -> 0
A36: 33 | C36: Spelling bank | D36: Phase 2 · Structure | H36: =IF(E36="Yes",10+IF(AND(F36<>"",F36>=IF(33<=7,3,IF(33<=14,5,IF(33<=21,7,IF(33<=42,8,10))))),2,0)+IF(G36>0,MIN(G36,3),0)+0+IF(MOD(I36,7)=0,IF(I36>0,5,0),0),IF(E36="Lite",3,0)) -> 0 | I36: =IF(OR(E36="Yes",E36="Lite"),IF(OR(E35="Yes",E35="Lite"),I35+1,1),IF(E36="Freeze",I35,0)) -> 0
A37: 34 | C37: Spelling bank | D37: Phase 2 · Structure | H37: =IF(E37="Yes",10+IF(AND(F37<>"",F37>=IF(34<=7,3,IF(34<=14,5,IF(34<=21,7,IF(34<=42,8,10))))),2,0)+IF(G37>0,MIN(G37,3),0)+0+IF(MOD(I37,7)=0,IF(I37>0,5,0),0),IF(E37="Lite",3,0)) -> 0 | I37: =IF(OR(E37="Yes",E37="Lite"),IF(OR(E36="Yes",E36="Lite"),I36+1,1),IF(E37="Freeze",I36,0)) -> 0
A38: 35 | C38: Spelling bank | D38: Phase 2 · Structure | H38: =IF(E38="Yes",10+IF(AND(F38<>"",F38>=IF(35<=7,3,IF(35<=14,5,IF(35<=21,7,IF(35<=42,8,10))))),2,0)+IF(G38>0,MIN(G38,3),0)+0+IF(MOD(I38,7)=0,IF(I38>0,5,0),0),IF(E38="Lite",3,0)) -> 0 | I38: =IF(OR(E38="Yes",E38="Lite"),IF(OR(E37="Yes",E37="Lite"),I37+1,1),IF(E38="Freeze",I37,0)) -> 0
A39: 36 | C39: Explain it | D39: Phase 2 · Structure | H39: =IF(E39="Yes",10+IF(AND(F39<>"",F39>=IF(36<=7,3,IF(36<=14,5,IF(36<=21,7,IF(36<=42,8,10))))),2,0)+IF(G39>0,MIN(G39,3),0)+0+IF(MOD(I39,7)=0,IF(I39>0,5,0),0),IF(E39="Lite",3,0)) -> 0 | I39: =IF(OR(E39="Yes",E39="Lite"),IF(OR(E38="Yes",E38="Lite"),I38+1,1),IF(E39="Freeze",I38,0)) -> 0
A40: 37 | C40: Explain it | D40: Phase 2 · Structure | H40: =IF(E40="Yes",10+IF(AND(F40<>"",F40>=IF(37<=7,3,IF(37<=14,5,IF(37<=21,7,IF(37<=42,8,10))))),2,0)+IF(G40>0,MIN(G40,3),0)+0+IF(MOD(I40,7)=0,IF(I40>0,5,0),0),IF(E40="Lite",3,0)) -> 0 | I40: =IF(OR(E40="Yes",E40="Lite"),IF(OR(E39="Yes",E39="Lite"),I39+1,1),IF(E40="Freeze",I39,0)) -> 0
A41: 38 | C41: Explain it | D41: Phase 2 · Structure | H41: =IF(E41="Yes",10+IF(AND(F41<>"",F41>=IF(38<=7,3,IF(38<=14,5,IF(38<=21,7,IF(38<=42,8,10))))),2,0)+IF(G41>0,MIN(G41,3),0)+0+IF(MOD(I41,7)=0,IF(I41>0,5,0),0),IF(E41="Lite",3,0)) -> 0 | I41: =IF(OR(E41="Yes",E41="Lite"),IF(OR(E40="Yes",E40="Lite"),I40+1,1),IF(E41="Freeze",I40,0)) -> 0
...

Sheet Weekly Goals
A1: Weekly Goals — print and stick inside the notebook cover
A3: Week | B3: Days | C3: Primary Goal | D3: Secondary Goal | E3: Achieved?
A4: 1 | B4: 1–7 | C4: Build daily ritual. Finish every session. | D4: Make desk distraction-free. | E4: ☐
A5: 2 | B5: 8–14 | C5: Speed-drill habit: alphabet + 60-sec count. | D5: Introduce 5-word spelling drill. | E5: ☐
A6: 3 | B6: 15–21 | C6: Story mode: 10-line story by Day 20. | D6: Use simple connectors (and, but, then, so). | E6: ☐
A7: 4 | B7: 22–28 | C7: 1 short paragraph daily (topic→3 ideas→end). | D7: Spelling bank: 10 new words mastered. | E7: ☐
A8: 5 | B8: 29–35 | C8: Use 5 connectors fluently. | D8: Spelling bank: 20 new words total. | E8: ☐
A9: 6 | B9: 36–42 | C9: Two-paragraph explanation pieces (Binocs-style). | D9: Self-check spelling before review. | E9: ☐
A10: 7 | B10: 43–49 | C10: 2 paragraphs in 10 minutes (timed). | D10: Begin opinion writing. | E10: ☐
A11: 8 | B11: 50–56 | C11: Opinion paragraph: 2 reasons + 1 example. | D11: Re-read & improve one line per day. | E11: ☐
A12: 9 | B12: 57–60 | C12: Full one-page piece (Class 6 style). | D12: Grand Final + reflection. | E12: ☐

Sheet Boss Challenges
A1: Boss Challenge Days — earn +15 XP and a special badge
A3: Day | B3: Boss Name | C3: Challenge | D3: Reward Badge | E3: Cleared?
A4: 10 | B4: Friend Story | C4: Write a 10-line story starring Arsh, Varad and yourself. | D4: 🟨 Story Builder | E4: ☐
A5: 20 | B5: Phase 1 Boss | C5: Choose one Day 1–19 prompt and rewrite it better and longer. | D5: 🟥 Boss Slayer I | E5: ☐
A6: 30 | B6: Halfway Hero | C6: Two short paragraphs explaining how YOU would teach writing. | D6: 🟪 Halfway Hero | E6: ☐
A7: 40 | B7: Phase 2 Boss | C7: Explain Roblox/Minecraft to an alien in 2 paragraphs. | D7: 🟥 Boss Slayer II | E7: ☐
A8: 50 | B8: Opinion Duel | C8: Take a side: 'Phones in school — yes or no?' Reasons + example. | D8: 🟧 Opinion Warrior | E8: ☐
A9: 60 | B9: Grand Final | C9: Write a full one-page piece: 'How I became a writer in 60 days.' | D9: 🟫 Class 6 Champion | E9: ☐

Sheet Spelling Bank
A1: Spelling Bank — 5 new words per week from Week 2
A3: Week | B3: Words | C3: Mastered? | D3: Notes
A4: 2 | B4: because, friend, school, before, every | C4: ☐
A5: 3 | B5: people, special, beautiful, favourite, different | C5: ☐
A6: 4 | B6: important, together, another, between, through | C6: ☐
A7: 5 | B7: around, almost, always, never, sometimes | C7: ☐
A8: 6 | B8: remember, forget, believe, decide, choose | C8: ☐
A9: 7 | B9: carefully, quickly, slowly, quietly, suddenly | C9: ☐
A10: 8 | B10: answer, question, problem, idea, sentence | C10: ☐
A11: 9 | B11: character, hero, villain, challenge, mission | C11: ☐

Sheet Rewards
A1: Milestone Rewards — pre-agree these with Arnav
A3: Milestone | B3: Reward (suggested) | C3: Agreed reward | D3: Claimed?
A4: Day 7 | B4: Pick the family movie night. | D4: ☐
A5: Day 14 | B5: Choose Saturday dinner. | D5: ☐
A6: Day 21 | B6: Extra 30 min Roblox/Minecraft on the weekend. | D6: ☐
A7: Day 30 | B7: Halfway: new notebook + pen set OR Robux/skin top-up. | D7: ☐
A8: Day 45 | B8: Friends-over-for-pizza evening. | D8: ☐
A9: Day 60 | B9: Grand reward (pre-agreed bigger item or experience). | D9: ☐

Sheet How to use
A1: How to use this tracker
A3: 1. | B3: Every day, open the 'Daily Log' tab.
A4: 2. | B4: Fill in the Date column.
A5: 3. | B5: Set 'Mission Done?' to one of: Yes / Lite / Freeze / No.
B6: • Yes = full mission completed (full XP)
B7: • Lite = 5-min Lite Day (small XP, streak preserved)
B8: • Freeze = used your weekly streak freeze (streak preserved, 0 XP)
B9: • No = skipped (streak resets)
A10: 4. | B10: Fill in 'Lines Written' (optional) and 'Spell Words Used' (max 3 counts).
A11: 5. | B11: Set the mood (1–5) if you like.
A12: 6. | B12: Watch the Dashboard update automatically. Streak, XP and Level all live.
A14: Tips for parents:
A15: • | B15: Mark XP together with Arnav. The ritual matters as much as the numbers.
A16: • | B16: Print the Weekly Goals sheet and stick it inside his notebook cover.
A17: • | B17: Boss Day arriving? Plan the celebration in advance — it's the hook.
A18: • | B18: If three days in a row are 'No', stop and read the Recovery section of the program.
